This happened when attemping to clone a repo on a remote machine, strack trace was visible on remote machine. Attempt at reproducing failed, running command again suceeded. 

    Cloning into '/etc/supervisor'...
    /opt/gitlab/embedded/lib/ruby/2.1.0/net/protocol.rb:153:in `read_nonblock': end of file reached (EOFError)
        from /opt/gitlab/embedded/lib/ruby/2.1.0/net/protocol.rb:153:in `rbuf_fill'
        from /opt/gitlab/embedded/lib/ruby/2.1.0/net/protocol.rb:134:in `readuntil'
        from /opt/gitlab/embedded/lib/ruby/2.1.0/net/protocol.rb:144:in `readline'
        from /opt/gitlab/embedded/lib/ruby/2.1.0/net/http/response.rb:39:in `read_status_line'
        from /opt/gitlab/embedded/lib/ruby/2.1.0/net/http/response.rb:28:in `read_new'
        from /opt/gitlab/embedded/lib/ruby/2.1.0/net/http.rb:1408:in `block in transport_request'
        from /opt/gitlab/embedded/lib/ruby/2.1.0/net/http.rb:1405:in `catch'
        from /opt/gitlab/embedded/lib/ruby/2.1.0/net/http.rb:1405:in `transport_request'
        from /opt/gitlab/embedded/lib/ruby/2.1.0/net/http.rb:1378:in `request'
        from /opt/gitlab/embedded/service/gitlab-shell/lib/gitlab_net.rb:97:in `block in post'
        from /opt/gitlab/embedded/lib/ruby/2.1.0/net/http.rb:853:in `start'
        from /opt/gitlab/embedded/service/gitlab-shell/lib/gitlab_net.rb:97:in `post'
        from /opt/gitlab/embedded/service/gitlab-shell/lib/gitlab_net.rb:27:in `allowed?'
        from /opt/gitlab/embedded/service/gitlab-shell/lib/gitlab_shell.rb:64:in `validate_access'
        from /opt/gitlab/embedded/service/gitlab-shell/lib/gitlab_shell.rb:25:in `exec'
        from /opt/gitlab/embedded/service/gitlab-shell/bin/gitlab-shell:20:in `<main>'
    fatal: Could not read from remote repository.

    Please make sure you have the correct access rights
    and the repository exists.

